#VRML_SIM R2020b utf8
WorldInfo {
  gravity 9.8
  basicTimeStep 10
  FPS 30
  coordinateSystem "NUE"
}
Viewpoint {
  orientation -0.7344248600855078 -0.6188996911074859 -0.2785377842150706 1.099551614722395
  position -0.505339714507685 0.7121052606634438 0.5236247775568186
}
TexturedBackground {
}
TexturedBackgroundLight {
}
Floor {
}
DEF robot Robot {
  translation 4.3596e-05 0.024 -5.39866e-11
  rotation -4.796411191243282e-06 1.2093257745805391e-07 -0.9999999999884901 0.0004707986511206568
  children [
    InertialUnit {
    }
    Accelerometer {
    }
    DEF body Solid {
      children [
        DEF body Shape {
          appearance PBRAppearance {
          }
          geometry Box {
            size 0.26 0.03 0.1
          }
        }
      ]
      name "solid(4)"
      boundingObject USE body
      physics Physics {
      }
    }
    DEF RF Transform {
      translation 0.135 0 0.05
      rotation 0 0 1 -1.57
      children [
        DEF RF0Shape Shape {
          appearance Appearance {
            material Material {
            }
          }
          geometry Cylinder {
            height 0.01
            radius 0.01
          }
        }
        DEF RF0 HingeJoint {
          jointParameters HingeJointParameters {
            position -1.6139266072113463e-07
            axis 0 1 0
          }
          device [
            DEF RF0 PositionSensor {
              name "RF0 sensor"
            }
            RotationalMotor {
              name "RF0"
            }
          ]
          endPoint DEF RF0 Solid {
            translation 1.572970000000064e-05 0 2.5386581353453695e-12
            rotation 7.736827828154128e-08 -0.2842225900694525 -0.9587583216297034 5.646734035461092e-07
            children [
              DEF half_L0 Transform {
                translation 0 0.015 0
                children [
                  DEF L0 Shape {
                    appearance Appearance {
                      material Material {
                      }
                    }
                    geometry Box {
                      size 0.01 0.03 0.01
                    }
                  }
                  DEF L0 Transform {
                    translation 0 0.015 0
                    rotation 0 0 1 1.57
                    children [
                      DEF RF1Shape Shape {
                        appearance Appearance {
                          material Material {
                          }
                        }
                        geometry Cylinder {
                          height 0.01
                          radius 0.01
                        }
                      }
                      DEF RF1 HingeJoint {
                        jointParameters HingeJointParameters {
                          position -1.0662498779211016e-07
                          axis 0 1 0
                        }
                        device [
                          DEF RF1 PositionSensor {
                            name "RF1 sensor"
                          }
                          RotationalMotor {
                            name "RF1"
                          }
                        ]
                        endPoint Solid {
                          rotation 0 -0.9999999999999999 0 1.0745380149674385e-07
                          children [
                            DEF half_L1 Transform {
                              translation 0 0 0.035
                              children [
                                DEF L1 Transform {
                                  translation 0 0 0.035
                                  children [
                                    DEF RF2Shape Shape {
                                      appearance Appearance {
                                        material Material {
                                        }
                                      }
                                      geometry Cylinder {
                                        height 0.01
                                        radius 0.01
                                      }
                                    }
                                    DEF RF2 HingeJoint {
                                      jointParameters HingeJointParameters {
                                        position 8.60201419139215e-08
                                        axis 0 1 0
                                      }
                                      device [
                                        DEF RF2 PositionSensor {
                                          name "RF2 sensor"
                                        }
                                        RotationalMotor {
                                          name "RF2"
                                        }
                                      ]
                                      endPoint DEF RFL2 Solid {
                                        translation -7.838815368927162e-10 1.294593332534788e-08 1.023386454487153e-09
                                        rotation 0.0018228060283082324 0.7938664868038859 0.6080893672050508 1.1920928955078128e-07
                                        children [
                                          DEF half_L2 Transform {
                                            translation 0.025 0 0
                                            children [
                                              DEF L2Shape Shape {
                                                appearance Appearance {
                                                  material Material {
                                                  }
                                                }
                                                geometry Box {
                                                  size 0.05 0.01 0.01
                                                }
                                              }
                                              DEF L2 Transform {
                                                translation 0.025 0 0
                                                children [
                                                  DEF half_L3 Transform {
                                                    translation 0 -0.012 0
                                                    rotation 1 0 0 4.692820414042842e-06
                                                    children [
                                                      DEF RFL3 Solid {
                                                        children [
                                                          DEF RF TouchSensor {
                                                            children [
                                                              DEF RFL3_shape Shape {
                                                                appearance Appearance {
                                                                  material Material {
                                                                  }
                                                                }
                                                                geometry Box {
                                                                  size 0.01 0.024 0.01
                                                                }
                                                              }
                                                            ]
                                                            name "RF touch sensor"
                                                            boundingObject USE RFL3_shape
                                                          }
                                                        ]
                                                        boundingObject USE RFL3_shape
                                                        physics Physics {
                                                        }
                                                      }
                                                    ]
                                                  }
                                                ]
                                              }
                                            ]
                                          }
                                        ]
                                        boundingObject USE RF2Shape
                                        physics Physics {
                                        }
                                      }
                                    }
                                  ]
                                }
                                DEF L1 Shape {
                                  appearance Appearance {
                                    material Material {
                                    }
                                  }
                                  geometry Box {
                                    size 0.01 0.01 0.07
                                  }
                                }
                              ]
                            }
                          ]
                          boundingObject USE RF1Shape
                          physics Physics {
                          }
                        }
                      }
                    ]
                  }
                ]
              }
            ]
            boundingObject USE RF0Shape
            physics Physics {
            }
          }
        }
      ]
    }
    DEF RH Transform {
      translation -0.135 0 0.05
      rotation 0 0 1 -1.57
      children [
        DEF RH0Shape Shape {
          appearance Appearance {
            material Material {
            }
          }
          geometry Cylinder {
            height 0.01
            radius 0.01
          }
        }
        DEF RH0 HingeJoint {
          jointParameters HingeJointParameters {
            position -1.6135525982008403e-07
            axis 0 1 0
          }
          device [
            PositionSensor {
              name "RH0 sensor"
            }
            RotationalMotor {
              name "RH0"
            }
          ]
          endPoint DEF RH0 Solid {
            translation 1.5729700000000633e-05 0 2.5380698303921115e-12
            rotation 7.736918539234041e-08 -0.28343381975906246 -0.9589917986181015 5.662441253662128e-07
            children [
              DEF half_L0 Transform {
                translation 0 -0.015 0
                children [
                  DEF L0 Shape {
                    appearance Appearance {
                      material Material {
                      }
                    }
                    geometry Box {
                      size 0.01 0.03 0.01
                    }
                  }
                  DEF L0 Transform {
                    translation 0 -0.015 0
                    rotation 0 0 1 1.57
                    children [
                      DEF RH1Shape Shape {
                        appearance Appearance {
                          material Material {
                          }
                        }
                        geometry Cylinder {
                          height 0.01
                          radius 0.01
                        }
                      }
                      DEF RH1 HingeJoint {
                        jointParameters HingeJointParameters {
                          position 1.0649196247374568e-07
                          axis 0 1 0
                        }
                        device [
                          PositionSensor {
                            name "RH1 sensor"
                          }
                          RotationalMotor {
                            name "RH1"
                          }
                        ]
                        endPoint Solid {
                          rotation 0 1 0 1.0745380149674385e-07
                          children [
                            DEF half_L1 Transform {
                              translation 0 0 0.035
                              children [
                                DEF L1 Transform {
                                  translation 0 0 0.035
                                  children [
                                    DEF RH2Shape Shape {
                                      appearance Appearance {
                                        material Material {
                                        }
                                      }
                                      geometry Cylinder {
                                        height 0.01
                                        radius 0.01
                                      }
                                    }
                                    DEF RH2 HingeJoint {
                                      jointParameters HingeJointParameters {
                                        position 8.557539761085326e-08
                                        axis 0 1 0
                                      }
                                      device [
                                        PositionSensor {
                                          name "RH2 sensor"
                                        }
                                        RotationalMotor {
                                          name "RH2"
                                        }
                                      ]
                                      endPoint DEF RFL2 Solid {
                                        translation -7.627542417297173e-10 1.4721893364100234e-08 2.6757448044887034e-09
                                        rotation -0.0467553330189179 0.4891678122658654 -0.870935583311026 1.2990531157078367e-07
                                        children [
                                          DEF half_L2 Transform {
                                            translation -0.025 0 0
                                            children [
                                              DEF L2Shape Shape {
                                                appearance Appearance {
                                                  material Material {
                                                  }
                                                }
                                                geometry Box {
                                                  size 0.05 0.01 0.01
                                                }
                                              }
                                              DEF L2 Transform {
                                                translation -0.025 0 0
                                                children [
                                                  DEF half_L3 Transform {
                                                    translation 0 -0.012 0
                                                    children [
                                                      DEF RFL3 Solid {
                                                        children [
                                                          DEF RH TouchSensor {
                                                            children [
                                                              DEF RHL3 Shape {
                                                                appearance Appearance {
                                                                  material Material {
                                                                  }
                                                                }
                                                                geometry Box {
                                                                  size 0.01 0.024 0.01
                                                                }
                                                              }
                                                            ]
                                                            name "RH touch sensor"
                                                            boundingObject USE RHL3
                                                          }
                                                        ]
                                                        boundingObject USE RHL3
                                                        physics Physics {
                                                        }
                                                      }
                                                    ]
                                                  }
                                                ]
                                              }
                                            ]
                                          }
                                        ]
                                        boundingObject USE RH2Shape
                                        physics Physics {
                                        }
                                      }
                                    }
                                  ]
                                }
                                DEF L1 Shape {
                                  appearance Appearance {
                                    material Material {
                                    }
                                  }
                                  geometry Box {
                                    size 0.01 0.01 0.07
                                  }
                                }
                              ]
                            }
                          ]
                          boundingObject USE RH1Shape
                          physics Physics {
                          }
                        }
                      }
                    ]
                  }
                ]
              }
            ]
            name "solid(2)"
            boundingObject USE RH0Shape
            physics Physics {
            }
          }
        }
      ]
    }
    DEF LF Transform {
      translation 0.135 0 -0.05
      rotation 0 0 -1 1.57
      children [
        DEF LF0Shape Shape {
          appearance Appearance {
            material Material {
            }
          }
          geometry Cylinder {
            height 0.01
            radius 0.01
          }
        }
        DEF LF0 HingeJoint {
          jointParameters HingeJointParameters {
            position 1.6139533924964074e-07
            axis 0 1 0
          }
          device [
            PositionSensor {
              name "LF0 sensor"
            }
            RotationalMotor {
              name "LF0"
            }
          ]
          endPoint DEF LF0 Solid {
            translation 1.5729700000000636e-05 0 -2.5387002669481785e-12
            rotation -7.736956165571063e-08 0.28422261653845576 -0.9587583137830035 5.646734035461092e-07
            children [
              DEF LF_half_L0 Transform {
                translation 0 0.015 0
                children [
                  DEF LF_L0 Shape {
                    appearance Appearance {
                      material Material {
                      }
                    }
                    geometry Box {
                      size 0.01 0.03 0.01
                    }
                  }
                  DEF LF_L0 Transform {
                    translation 0 0.015 0
                    rotation 0 0 1 1.57
                    children [
                      DEF LF1Shape Shape {
                        appearance Appearance {
                          material Material {
                          }
                        }
                        geometry Cylinder {
                          height 0.01
                          radius 0.01
                        }
                      }
                      DEF LF1 HingeJoint {
                        jointParameters HingeJointParameters {
                          position 1.0661920067668223e-07
                          axis 0 1 0
                        }
                        device [
                          PositionSensor {
                            name "LF1 sensor"
                          }
                          RotationalMotor {
                            name "LF1"
                          }
                        ]
                        endPoint Solid {
                          rotation 0 1 0 1.0745380149674385e-07
                          children [
                            DEF half_L1 Transform {
                              translation 0 0 -0.035
                              children [
                                DEF LF_L1 Transform {
                                  translation 0 0 -0.035
                                  children [
                                    DEF LF2Shape Shape {
                                      appearance Appearance {
                                        material Material {
                                        }
                                      }
                                      geometry Cylinder {
                                        height 0.01
                                        radius 0.01
                                      }
                                    }
                                    DEF LF2 HingeJoint {
                                      jointParameters HingeJointParameters {
                                        position -8.60221254228577e-08
                                        axis 0 1 0
                                      }
                                      device [
                                        PositionSensor {
                                          name "LF2 sensor"
                                        }
                                        RotationalMotor {
                                          name "LF2"
                                        }
                                      ]
                                      endPoint DEF LFL2 Solid {
                                        translation -7.840206590215705e-10 1.2945959838861486e-08 -1.0233955338108392e-09
                                        rotation -0.001823213553340366 -0.793864820418157 0.6080915414596607 1.1920928955078128e-07
                                        children [
                                          DEF LF_half_L2 Transform {
                                            translation 0.025 0 0
                                            children [
                                              DEF LF_L2Shape Shape {
                                                appearance Appearance {
                                                  material Material {
                                                  }
                                                }
                                                geometry Box {
                                                  size 0.05 0.01 0.01
                                                }
                                              }
                                              DEF LF_L2 Transform {
                                                translation 0.025 0 0
                                                children [
                                                  DEF LF_half_L3 Transform {
                                                    translation 0 -0.012 0
                                                    children [
                                                      DEF LFFL3 Solid {
                                                        children [
                                                          DEF LF TouchSensor {
                                                            children [
                                                              DEF LF_L3 Shape {
                                                                appearance Appearance {
                                                                  material Material {
                                                                  }
                                                                }
                                                                geometry Box {
                                                                  size 0.01 0.024 0.01
                                                                }
                                                              }
                                                            ]
                                                            name "LF touch sensor"
                                                            boundingObject USE LF_L3
                                                          }
                                                        ]
                                                        boundingObject USE LF_L3
                                                        physics Physics {
                                                        }
                                                      }
                                                    ]
                                                  }
                                                ]
                                              }
                                            ]
                                          }
                                        ]
                                        boundingObject USE LF2Shape
                                        physics Physics {
                                        }
                                      }
                                    }
                                  ]
                                }
                                DEF LF_L1 Shape {
                                  appearance Appearance {
                                    material Material {
                                    }
                                  }
                                  geometry Box {
                                    size 0.01 0.01 0.07
                                  }
                                }
                              ]
                            }
                          ]
                          boundingObject USE LF1Shape
                          physics Physics {
                          }
                        }
                      }
                    ]
                  }
                ]
              }
            ]
            name "solid(1)"
            boundingObject USE LF0Shape
            physics Physics {
            }
          }
        }
      ]
    }
    DEF LH Transform {
      translation -0.135 0 -0.05
      rotation 0 0 1 -1.57
      children [
        DEF LH0Shape Shape {
          appearance Appearance {
            material Material {
            }
          }
          geometry Cylinder {
            height 0.01
            radius 0.01
          }
        }
        DEF LH0 HingeJoint {
          jointParameters HingeJointParameters {
            position 1.6136424852021782e-07
            axis 0 1 0
          }
          device [
            PositionSensor {
              name "LH0 sensor"
            }
            RotationalMotor {
              name "LH0"
            }
          ]
          endPoint DEF LH0 Solid {
            translation 1.5729700000000626e-05 0 -2.5382112199486058e-12
            rotation -7.738282817001314e-08 0.28304215100711855 -0.9591074709088954 5.670278546345386e-07
            children [
              DEF LH_half_L0 Transform {
                translation 0 -0.015 0
                children [
                  DEF LH_L0 Shape {
                    appearance Appearance {
                      material Material {
                      }
                    }
                    geometry Box {
                      size 0.01 0.03 0.01
                    }
                  }
                  DEF LH_L0 Transform {
                    translation 0 -0.015 0
                    rotation 0 0 1 1.57
                    children [
                      DEF LH1Shape Shape {
                        appearance Appearance {
                          material Material {
                          }
                        }
                        geometry Cylinder {
                          height 0.01
                          radius 0.01
                        }
                      }
                      DEF LH1 HingeJoint {
                        jointParameters HingeJointParameters {
                          position -1.064886516743968e-07
                          axis 0 1 0
                        }
                        device [
                          PositionSensor {
                            name "LH1 sensor"
                          }
                          RotationalMotor {
                            name "LH1"
                          }
                        ]
                        endPoint Solid {
                          rotation 0 -1 0 1.0745380149674385e-07
                          children [
                            DEF half_L1 Transform {
                              translation 0 0 -0.035
                              children [
                                DEF LH_L1 Transform {
                                  translation 0 0 -0.035
                                  children [
                                    DEF LH2Shape Shape {
                                      appearance Appearance {
                                        material Material {
                                        }
                                      }
                                      geometry Cylinder {
                                        height 0.01
                                        radius 0.01
                                      }
                                    }
                                    DEF LH2 HingeJoint {
                                      jointParameters HingeJointParameters {
                                        position -8.557469666214956e-08
                                        axis 0 1 0
                                      }
                                      device [
                                        PositionSensor {
                                          name "LH2 sensor"
                                        }
                                        RotationalMotor {
                                          name "LH2"
                                        }
                                      ]
                                      endPoint DEF LHL2 Solid {
                                        translation -7.628864863174509e-10 1.472188711909572e-08 -2.6758533277226508e-09
                                        rotation 0.04712185107495625 -0.47678045274175707 -0.877758469645628 1.3328003749250115e-07
                                        children [
                                          DEF LH_half_L2 Transform {
                                            translation -0.025 0 0
                                            children [
                                              DEF LH_L2Shape Shape {
                                                appearance Appearance {
                                                  material Material {
                                                  }
                                                }
                                                geometry Box {
                                                  size 0.05 0.01 0.01
                                                }
                                              }
                                              DEF LH_L2 Transform {
                                                translation -0.025 0 0
                                                children [
                                                  DEF LH_half_L3 Transform {
                                                    translation 0 -0.012 0
                                                    children [
                                                      DEF LHL3 Solid {
                                                        children [
                                                          DEF LH TouchSensor {
                                                            children [
                                                              DEF LH3 Shape {
                                                                appearance Appearance {
                                                                  material Material {
                                                                  }
                                                                }
                                                                geometry Box {
                                                                  size 0.01 0.024 0.01
                                                                }
                                                              }
                                                            ]
                                                            name "LH touch sensor"
                                                            boundingObject USE LH3
                                                          }
                                                        ]
                                                        boundingObject USE LH3
                                                        physics Physics {
                                                        }
                                                      }
                                                    ]
                                                  }
                                                ]
                                              }
                                            ]
                                          }
                                        ]
                                        boundingObject USE LH2Shape
                                        physics Physics {
                                        }
                                      }
                                    }
                                  ]
                                }
                                DEF LH_L1 Shape {
                                  appearance Appearance {
                                    material Material {
                                    }
                                  }
                                  geometry Box {
                                    size 0.01 0.01 0.07
                                  }
                                }
                              ]
                            }
                          ]
                          boundingObject USE LH1Shape
                          physics Physics {
                          }
                        }
                      }
                    ]
                  }
                ]
              }
            ]
            name "solid(3)"
            boundingObject USE LH0Shape
            physics Physics {
            }
          }
        }
      ]
    }
  ]
  boundingObject Box {
    size 0.01 0.01 0.01
  }
  physics Physics {
  }
  controller "GeckoRunner"
}
